Workbook

Sheet README
A1: UCG Platform - Stress Test Feedback (Nate)
A2: Companion to docs/plans/2026-08-19-uat-stress-test-plan.md
A4: HOW TO USE THIS FILE
A5: 1. Go to the Findings tab. Every step from the plan is already there, in order.
A6: 2. Fill in the Result column for EVERY step - including the ones that pass.
A7: A PASS row takes two seconds and is what makes the untested gaps visible.
A8: 3. Only fill the rest of the row when it is NOT a plain PASS.
A9: 4. Anything BROKEN: file it in-app first (Report a problem), THEN add the row here.
A10: The in-app widget captures the console-error buffer, which is overwritten as you
A11: keep clicking. Start that description with the Finding ID and your initials.
A12: 5. Blank rows at the bottom of Findings are for anything not tied to a step.
A13: 6. Answer the Decisions tab whenever you like - no testing needed for those.
... A47: PROGRESS
A48: Steps in the plan | B48: =COUNTIF(Findings!A3:A2000,"?-??")
A49: Steps with a Result filled in | B49: =COUNTIFS(Findings!A3:A2000,"?-??",Findings!D3:D2000,"<>")
A50: Still to do | B50: =COUNTIF(Findings!A3:A2000,"?-??")-COUNTIFS(Findings!A3:A2000,"?-??",Findings!D3:D2000,"<>")
A52: PASS | B52: =COUNTIF(Findings!D3:D2000,"PASS")
A53: FAIL | B53: =COUNTIF(Findings!D3:D2000,"FAIL")
A54: MISSING | B54: =COUNTIF(Findings!D3:D2000,"MISSING")
A55: UNCLEAR | B55: =COUNTIF(Findings!D3:D2000,"UNCLEAR")
A56: BLOCKED | B56: =COUNTIF(Findings!D3:D2000,"BLOCKED")
A58: S1 blockers | B58: =COUNTIF(Findings!F3:F2000,"S1")
A59: S2 major | B59: =COUNTIF(Findings!F3:F2000,"S2")
A60: Decisions raised (D) | B60: =COUNTIF(Findings!F3:F2000,"D")

Sheet Findings
A1: Step ID | B1: Lane | C1: Step (what to do) | D1: Result | E1: Finding ID | F1: Severity | G1: What you expected | H1: What actually happened (exact error text) | I1: Timestamp (local + tz) | J1: Hard reload fix it? | K1: Device / browser | L1: Signed in as | M1: Screenshot(s) | N1: Reported in-app? | O1: Notes
A2: M-07 | B2: =IFERROR(LEFT(A2,FIND("-",A2)-1),"") | C2: EXAMPLE ROW - delete or overwrite me | D2: FAIL | E2: M-07-01 | F2: S1 | G2: 3-D Secure challenge appears, then the payment completes | H2: Challenge appeared, I approved it, then "Something went wrong" and the cart still had the item | I2: 2026-08-19 14:32 PT | J2: N | K2: Win 11 / Chrome 141 | L2: Athlete (ZZTEST-Robin) | M2: M-07-01_01_JB.png, M-07-01_02_JB.png | N2: Y | O2: Reproduced twice. Stripe dashboard shows no payment attempt at all.
A3: A - Accounts, auth & security
A4: A-01 | B4: =IFERROR(LEFT(A4,FIND("-",A4)-1),"") | C4: Sign up a brand-new account from scratch
A5: A-02 | B5: =IFERROR(LEFT(A5,FIND("-",A5)-1),"") | C5: Signed out: go directly to #/admin/league
A6: A-03 | B6: =IFERROR(LEFT(A6,FIND("-",A6)-1),"") | C6: Role-less athlete: try the 3 admin routes (watch for a flash of real UI)
A7: A-04 | B7: =IFERROR(LEFT(A7,FIND("-",A7)-1),"") | C7: Refresh 3x while on an admin page as admin (no access-denied flash)
A8: A-05 | B8: =IFERROR(LEFT(A8,FIND("-",A8)-1),"") | C8: Sign out, then press browser Back
A9: A-06 | B9: =IFERROR(LEFT(A9,FIND("-",A9)-1),"") | C9: Forgot-password flow end to end
A10: A-07 | B10: =IFERROR(LEFT(A10,FIND("-",A10)-1),"") | C10: Admin sends an account invite; recipient sets a password
A11: A-08 | B11: =IFERROR(LEFT(A11,FIND("-",A11)-1),"") | C11: Enroll TOTP with a real authenticator app
A12: A-09 | B12: =IFERROR(LEFT(A12,FIND("-",A12)-1),"") | C12: Sign out, sign back in with TOTP (wrong code, then right)
A13: A-10 | B13: =IFERROR(LEFT(A13,FIND("-",A13)-1),"") | C13: Enroll a passkey on real hardware; sign in with it
A14: A-11 | B14: =IFERROR(LEFT(A14,FIND("-",A14)-1),"") | C14: Sign in as an admin with no MFA enrolled (the nag)
A15: A-12 | B15: =IFERROR(LEFT(A15,FIND("-",A15)-1),"") | C15: Nate: admin MFA reset break-glass
... A17: A-14 | B17: =IFERROR(LEFT(A17,FIND("-",A17)-1),"") | C17: Signed in on phone + desktop; change name on one
A18: M - Cart, pricing & Stripe checkout
A19: M-01 | B19: =IFERROR(LEFT(A19,FIND("-",A19)-1),"") | C19: Add one registration to cart; write down every number
A20: M-02 | B20: =IFERROR(LEFT(A20,FIND("-",A20)-1),"") | C20: Compare the Stripe page's numbers against the cart, to the cent
A21: M-03 | B21: =IFERROR(LEFT(A21,FIND("-",A21)-1),"") | C21: Pay with 4242; watch what happens after
A22: M-04 | B22: =IFERROR(LEFT(A22,FIND("-",A22)-1),"") | C22: Confirmation email vs the in-app receipt
A23: M-05 | B23: =IFERROR(LEFT(A23,FIND("-",A23)-1),"") | C23: Open the receipt PDF and actually print it
A24: M-06 | B24: =IFERROR(LEFT(A24,FIND("-",A24)-1),"") | C24: Checkout with the DECLINE card 4000...0002
A25: M-07 | B25: =IFERROR(LEFT(A25,FIND("-",A25)-1),"") | C25: Checkout with the 3-D SECURE card 4000 0025 0000 3155
A26: M-08 | B26: =IFERROR(LEFT(A26,FIND("-",A26)-1),"") | C26: Start a checkout and abandon it (close the tab mid-payment)
A27: M-09 | B27: =IFERROR(LEFT(A27,FIND("-",A27)-1),"") | C27: Browser Back button from inside Stripe checkout
A28: M-10 | B28: =IFERROR(LEFT(A28,FIND("-",A28)-1),"") | C28: Cart with registration + add-ons + a change fee together
A29: M-11 | B29: =IFERROR(LEFT(A29,FIND("-",A29)-1),"") | C29: Apply a promo/coupon code (visible in cart AND in Stripe)
A30: M-12 | B30: =IFERROR(LEFT(A30,FIND("-",A30)-1),"") | C30: Coupon that covers 100% of the total
... A38: M-20 | B38: =IFERROR(LEFT(A38,FIND("-",A38)-1),"") | C38: #/me/purchases vs the Stripe Dashboard test payments
A39: Z - Two-person concurrency (JOINT)
A40: Z-01 | B40: =IFERROR(LEFT(A40,FIND("-",A40)-1),"") | C40: SIMULTANEOUS CHECKOUT x3 - record BOTH invoice numbers verbatim
A41: Z-02 | B41: =IFERROR(LEFT(A41,FIND("-",A41)-1),"") | C41: Both register the SAME athlete for the SAME event at once
A42: Z-03 | B42: =IFERROR(LEFT(A42,FIND("-",A42)-1),"") | C42: Both fill the last capacity slots at once
A43: Z-04 | B43: =IFERROR(LEFT(A43,FIND("-",A43)-1),"") | C43: Both approve the SAME refund request at once
A44: Z-05 | B44: =IFERROR(LEFT(A44,FIND("-",A44)-1),"") | C44: Both save different changes to the same event settings
A45: Z-06 | B45: =IFERROR(LEFT(A45,FIND("-",A45)-1),"") | C45: Both enter a different score for the same athlete/apparatus
A46: E - Email & SMS deliverability
A47: E-01 | B47: =IFERROR(LEFT(A47,FIND("-",A47)-1),"") | C47: Trigger all 13 transactional emails; check arrival/spam/from/reply-to/phone
A48: E-02 | B48: =IFERROR(LEFT(A48,FIND("-",A48)-1),"") | C48: Per-event custom confirmation email body
...

Sheet Decisions
A1: Decisions needed - no testing required, just your answer
A3: # | B3: Topic | C3: The question | D3: Your answer
A4: D-1 | B4: Camps and club managers | C4: Spec SS-G says camps are individual self-registration only, but a club manager can still register athletes for one. Block it outright, or keep it as a convenience?
A5: D-2 | B5: Host payout timing | C5: The 'owed' formula is settled (gross before fees, refunds not deducted). WHEN payout happens is still just wording on the host page. Is '1 week after the event' the policy?
A6: D-3 | B6: Hosts and SMS | C6: Hosts currently get email only from the event Communicate page; SMS stays league-admin-only because each text bills UCG. Still right?
A7: D-4 | B7: Invoice numbering format | C7: Two formats coexist. Which one do you want on real financial records?
A8: D-5 | B8: Refund policy edges | C8: After-deadline is 75% before processing fees. Should add-ons follow the same 75% rule, or refund in full?
A9: D-6 | B9: Anything in Appendix A you think should not wait | C9: List anything from the known-gaps appendix you want prioritized, and why.
