Workbook

Sheet README
A1: UCG Preflight - Feedback Tracker
A2: One shared sheet. Julia works in 'Julia Findings', Nate in 'Nate Findings'.
A3: Companion to the UCG Preflight page / docs/plans/2026-08-19-uat-stress-test-plan.md
A5: HOW TO USE
A6: 1. Work in YOUR OWN Findings tab. Every step from the plan is already there, in order.
A7: 2. Fill in the Result column for EVERY step - including the ones that pass.
A8: A PASS row takes two seconds and is what makes the untested gaps visible.
A9: 3. Only fill the rest of a row when it is NOT a plain PASS.
A10: 4. Anything BROKEN: file it in-app first (Report a problem), THEN add the row here.
A11: The in-app widget captures the console-error buffer, which is overwritten as you
A12: keep clicking. Start that description with the Finding ID and your initials.
A13: 5. Blank rows at the bottom of each Findings tab are for anything not tied to a step.
... A43: PROGRESS
B44: Julia | C44: Nate
A45: Steps in the plan | B45: =COUNTIF('Julia Findings'!A3:A2000,"?-??") | C45: =COUNTIF('Nate Findings'!A3:A2000,"?-??")
A46: Steps with a Result filled in | B46: =COUNTIFS('Julia Findings'!A3:A2000,"?-??",'Julia Findings'!D3:D2000,"<>") | C46: =COUNTIFS('Nate Findings'!A3:A2000,"?-??",'Nate Findings'!D3:D2000,"<>")
A47: Still to do | B47: =COUNTIF('Julia Findings'!A3:A2000,"?-??")-COUNTIFS('Julia Findings'!A3:A2000,"?-??",'Julia Findings'!D3:D2000,"<>") | C47: =COUNTIF('Nate Findings'!A3:A2000,"?-??")-COUNTIFS('Nate Findings'!A3:A2000,"?-??",'Nate Findings'!D3:D2000,"<>")
A49: PASS | B49: =COUNTIF('Julia Findings'!D3:D2000,"PASS") | C49: =COUNTIF('Nate Findings'!D3:D2000,"PASS")
A50: FAIL | B50: =COUNTIF('Julia Findings'!D3:D2000,"FAIL") | C50: =COUNTIF('Nate Findings'!D3:D2000,"FAIL")
A51: MISSING | B51: =COUNTIF('Julia Findings'!D3:D2000,"MISSING") | C51: =COUNTIF('Nate Findings'!D3:D2000,"MISSING")
A52: UNCLEAR | B52: =COUNTIF('Julia Findings'!D3:D2000,"UNCLEAR") | C52: =COUNTIF('Nate Findings'!D3:D2000,"UNCLEAR")
A53: BLOCKED | B53: =COUNTIF('Julia Findings'!D3:D2000,"BLOCKED") | C53: =COUNTIF('Nate Findings'!D3:D2000,"BLOCKED")
A55: S1 blockers | B55: =COUNTIF('Julia Findings'!F3:F2000,"S1") | C55: =COUNTIF('Nate Findings'!F3:F2000,"S1")
A56: S2 major | B56: =COUNTIF('Julia Findings'!F3:F2000,"S2") | C56: =COUNTIF('Nate Findings'!F3:F2000,"S2")
A57: Decisions raised (D) | B57: =COUNTIF('Julia Findings'!F3:F2000,"D") | C57: =COUNTIF('Nate Findings'!F3:F2000,"D")

Sheet Julia Findings
A1: Step ID | B1: Lane | C1: Step (what to do) | D1: Result | E1: Finding ID | F1: Severity | G1: What you expected | H1: What actually happened (exact error text) | I1: Timestamp (local + tz) | J1: Hard reload fix it? | K1: Device / browser | L1: Signed in as | M1: Screenshot(s) | N1: Reported in-app? | O1: Notes
A2: M-07 | B2: M | C2: EXAMPLE ROW - delete or overwrite me | D2: FAIL | E2: M-07-01 | F2: S1 | G2: 3-D Secure challenge appears, then the payment completes | H2: Challenge appeared, I approved it, then "Something went wrong" and the cart still had the item | I2: 2026-08-19 14:32 PT | J2: N | K2: Win 11 / Chrome 141 | L2: Athlete (ZZTEST-Robin) | M2: M-07-01_01_JS.png | N2: Y | O2: Reproduced twice. Stripe dashboard shows no payment attempt at all.
A3: A - Accounts, auth & security
A4: A-01 | B4: A | C4: Sign up a brand-new account from scratch (ZZTEST- name, an address you can read)
A5: A-02 | B5: A | C5: While signed out, go directly to #/admin/league
A6: A-03 | B6: A | C6: Sign in as the role-less athlete (S-05), then go to #/admin/league, #/admin/finance, #/admin/refunds
A7: A-04 | B7: A | C7: Refresh the page while signed in as an admin, on an admin page
A8: A-05 | B8: A | C8: Sign out, then use the browser Back button
A9: A-06 | B9: A | C9: Forgot-password flow end to end
A10: A-07 | B10: A | C10: Admin sends an account invite: #/admin/members → open a person who has no account → Send account invite. (NOT "+ New Person" — that only creates the profile; A-07-01 was partly this step's wording.) Recipient clicks the link
A11: A-08 | B11: A | C11: Enroll TOTP on a fresh account with a real authenticator app
A12: A-09 | B12: A | C12: Sign out, sign back in with TOTP
A13: A-10 | B13: A | C13: Enroll a passkey on real hardware (Face ID / Touch ID / Windows Hello)
A14: A-11 | B14: A | C14: Sign in as an admin without MFA enrolled
A15: A-12 | B15: A | C15: Nate: exercise the admin MFA reset break-glass on the test account
... A17: A-14 | B17: A | C17: Sign in on your phone and desktop at once; change your name on one
A18: M - Cart, pricing & Stripe checkout
A19: M-01 | B19: M | C19: Add one event registration to the cart. Write down every number on the cart page: line item, subtotal, service fee, total
A20: M-02 | B20: M | C20: Click through to checkout. Compare the Stripe page's numbers against M-01, to the cent
A21: M-03 | B21: M | C21: Pay with 4242…. Watch what happens after the payment completes
A22: M-04 | B22: M | C22: Check the confirmation email against the receipt in-app
A23: M-05 | B23: M | C23: Open the invoice/receipt PDF and actually print it (or print-to-PDF)
A24: M-06 | B24: M | C24: Repeat a checkout with the decline card 4000…0002
A25: M-07 | B25: M | C25: Repeat with the 3-D Secure card 4000 0025 0000 3155
A26: M-08 | B26: M | C26: Start a checkout and abandon it — close the tab mid-payment. Wait 2 minutes, come back
A27: M-09 | B27: M | C27: Use the browser Back button from inside Stripe checkout
A28: M-10 | B28: M | C28: Build a cart with registration + add-ons + a change fee together
A29: M-11 | B29: M | C29: Apply a promo/coupon code
A30: M-12 | B30: M | C30: Apply a coupon that covers 100% of the total
... A38: M-20 | B38: M | C38: Compare #/me/purchases against the Stripe Dashboard test payments
A39: Z - Two-person concurrency (JOINT SESSION — book it)
A40: Z-01 | B40: Z | C40: Simultaneous checkout. Both of you get a cart ready with a different item. Count down 3-2-1 and click Pay at the same moment. Then write down both invoice numbers, verbatim, exactly as shown.
A41: Z-02 | B41: Z | C41: Simultaneous registration of the same athlete. Nate (as admin) and Julia (as club manager) both register the same athlete for the same event at the same moment
A42: Z-03 | B42: Z | C42: ✅ UNHELD 2026-08-24 — the capacity rework is live. Simultaneous capacity fill: set a per-discipline or per-level cap where you'll collide, both check out at once
A43: Z-04 | B43: Z | C43: Simultaneous refund approval. Both approve the same refund request at the same moment
A44: Z-05 | B44: Z | C44: Edit collision. Both open the same event's settings and save different changes
A45: Z-06 | B45: Z | C45: Judge collision. Both enter a different score for the same athlete/apparatus at the same time
A46: E - Email & SMS deliverability
A47: E-01 | B47: E | C47: Trigger each of these and check all four points: signup confirmation, password reset, account invite, club invite, membership welcome, payment/registration confirmation, waiver request, guardian waiver request, sanction submitted, sanction approved, refund requested, refund approved, refund rejected
A48: E-02 | B48: E | C48: Per-event confirmation email: set a custom body on an event, then register for it (spec §A/§I)
...

Sheet Nate Findings
A1: Step ID | B1: Lane | C1: Step (what to do) | D1: Result | E1: Finding ID | F1: Severity | G1: What you expected | H1: What actually happened (exact error text) | I1: Timestamp (local + tz) | J1: Hard reload fix it? | K1: Device / browser | L1: Signed in as | M1: Screenshot(s) | N1: Reported in-app? | O1: Notes
A2: M-07 | B2: M | C2: EXAMPLE ROW - delete or overwrite me | D2: FAIL | E2: M-07-01 | F2: S1 | G2: 3-D Secure challenge appears, then the payment completes | H2: Challenge appeared, I approved it, then "Something went wrong" and the cart still had the item | I2: 2026-08-19 14:32 PT | J2: N | K2: Win 11 / Chrome 141 | L2: Athlete (ZZTEST-Robin) | M2: M-07-01_01_NS.png | N2: Y | O2: Reproduced twice. Stripe dashboard shows no payment attempt at all.
A3: A - Accounts, auth & security
A4: A-01 | B4: A | C4: Sign up a brand-new account from scratch (ZZTEST- name, an address you can read)
A5: A-02 | B5: A | C5: While signed out, go directly to #/admin/league
A6: A-03 | B6: A | C6: Sign in as the role-less athlete (S-05), then go to #/admin/league, #/admin/finance, #/admin/refunds
A7: A-04 | B7: A | C7: Refresh the page while signed in as an admin, on an admin page
A8: A-05 | B8: A | C8: Sign out, then use the browser Back button
A9: A-06 | B9: A | C9: Forgot-password flow end to end
A10: A-07 | B10: A | C10: Admin sends an account invite: #/admin/members → open a person who has no account → Send account invite. (NOT "+ New Person" — that only creates the profile; A-07-01 was partly this step's wording.) Recipient clicks the link
A11: A-08 | B11: A | C11: Enroll TOTP on a fresh account with a real authenticator app
A12: A-09 | B12: A | C12: Sign out, sign back in with TOTP
A13: A-10 | B13: A | C13: Enroll a passkey on real hardware (Face ID / Touch ID / Windows Hello)
A14: A-11 | B14: A | C14: Sign in as an admin without MFA enrolled
A15: A-12 | B15: A | C15: Nate: exercise the admin MFA reset break-glass on the test account
... A17: A-14 | B17: A | C17: Sign in on your phone and desktop at once; change your name on one
A18: M - Cart, pricing & Stripe checkout
A19: M-01 | B19: M | C19: Add one event registration to the cart. Write down every number on the cart page: line item, subtotal, service fee, total
A20: M-02 | B20: M | C20: Click through to checkout. Compare the Stripe page's numbers against M-01, to the cent
A21: M-03 | B21: M | C21: Pay with 4242…. Watch what happens after the payment completes
A22: M-04 | B22: M | C22: Check the confirmation email against the receipt in-app
A23: M-05 | B23: M | C23: Open the invoice/receipt PDF and actually print it (or print-to-PDF)
A24: M-06 | B24: M | C24: Repeat a checkout with the decline card 4000…0002
A25: M-07 | B25: M | C25: Repeat with the 3-D Secure card 4000 0025 0000 3155
A26: M-08 | B26: M | C26: Start a checkout and abandon it — close the tab mid-payment. Wait 2 minutes, come back
A27: M-09 | B27: M | C27: Use the browser Back button from inside Stripe checkout
A28: M-10 | B28: M | C28: Build a cart with registration + add-ons + a change fee together
A29: M-11 | B29: M | C29: Apply a promo/coupon code
A30: M-12 | B30: M | C30: Apply a coupon that covers 100% of the total
... A38: M-20 | B38: M | C38: Compare #/me/purchases against the Stripe Dashboard test payments
A39: Z - Two-person concurrency (JOINT SESSION — book it)
A40: Z-01 | B40: Z | C40: Simultaneous checkout. Both of you get a cart ready with a different item. Count down 3-2-1 and click Pay at the same moment. Then write down both invoice numbers, verbatim, exactly as shown.
A41: Z-02 | B41: Z | C41: Simultaneous registration of the same athlete. Nate (as admin) and Julia (as club manager) both register the same athlete for the same event at the same moment
A42: Z-03 | B42: Z | C42: ✅ UNHELD 2026-08-24 — the capacity rework is live. Simultaneous capacity fill: set a per-discipline or per-level cap where you'll collide, both check out at once
A43: Z-04 | B43: Z | C43: Simultaneous refund approval. Both approve the same refund request at the same moment
A44: Z-05 | B44: Z | C44: Edit collision. Both open the same event's settings and save different changes
A45: Z-06 | B45: Z | C45: Judge collision. Both enter a different score for the same athlete/apparatus at the same time
A46: E - Email & SMS deliverability
A47: E-01 | B47: E | C47: Trigger each of these and check all four points: signup confirmation, password reset, account invite, club invite, membership welcome, payment/registration confirmation, waiver request, guardian waiver request, sanction submitted, sanction approved, refund requested, refund approved, refund rejected
A48: E-02 | B48: E | C48: Per-event confirmation email: set a custom body on an event, then register for it (spec §A/§I)
...

Sheet Decisions
A1: Decisions needed - no testing required, just Julia's answer
A3: # | B3: Topic | C3: The question | D3: Julia's answer
A4: D-1 | B4: Camps and club managers | C4: Spec SS-G says camps are individual self-registration only, but a club manager can still register athletes for one. Block it outright, or keep it as a convenience?
A5: D-2 | B5: Host payout timing | C5: The 'owed' formula is settled (gross before fees, refunds not deducted). WHEN payout happens is still just wording on the host page. Is '1 week after the event' the policy?
A6: D-3 | B6: Hosts and SMS | C6: Hosts currently get email only from the event Communicate page; SMS stays league-admin-only because each text bills UCG. Still right?
A7: D-4 | B7: Invoice numbering format | C7: Two formats coexist. Which one do you want on real financial records?
A8: D-5 | B8: Refund policy edges | C8: After-deadline is 75% before processing fees. Should add-ons follow the same 75% rule, or refund in full?
A9: D-6 | B9: Anything in the known-gaps appendix that should not wait | C9: List anything from Appendix A you want prioritized, and why.
